Workbook

Sheet Resumen
C2: Dinero | D2: Cantidad | G2: Dinero | H2: Cantidad
B3: Entregado últimos 12 meses | C3: =AI112 -> 19182031 | D3: =AG112 -> 144 | F3: Stock (+) | G3: =K112 -> 5114246.9 | H3: =J112 -> 49
B4: Entregado 2026 | C4: =Z112 -> 7841236.8 | D4: =X112 -> 59 | F4: Tránsito real (+) | G4: =N112 -> 4840000.5 | H4: =L112 -> 50
B5: Backlog (Abril) | C5: =W112 -> 7438180.9 | D5: =U112 -> 49 | F5: Tránsito proyectado (+) | G5: =Q112 -> 5752411.2 | H5: =O112 -> 64
B6: Cotizado (NEC 3) | C6: =AC112 -> 0 | D6: =AA112 -> 0 | F6: En proceso (+) | G6: =AM112 -> 1783945 | H6: =AK112 -> 17
B7: Presupuesto 2026 | C7: =AF112 -> 22548875 | D7: =AD112 -> 172 | F7: Inventario inicial | G7: =SUM(G3:G6) -> 17490604 | H7: =SUM(H3:H6) -> 180
B8: Cumplimiento presupuesto (Cantidad) | C8: =IFERROR((D4+D5)/D7,"0") -> 0.62790698 | F8: Backlog (-) | G8: =W112 -> 7438180.9 | H8: =U112 -> 49
B9: Cumplimiento presupuesto (Dinero) | C9: =IFERROR((C4+C5)/C7,"0") -> 0.67761331 | F9: Inventario final | G9: =G7-G8 -> 10052423 | H9: =H7-H8 -> 131
B10: Rotación (últimos 12 meses) | C10: =IFERROR((H9/((D3+D5)/12)),"0") -> 8.1450777 | F10: Solicitud de compras (+) | G10: =T112 -> 2069007.4 | H10: =R112 -> 20
B11: Rotación (últimos 12 meses) + solicitud | C11: =IFERROR((H11/((D3+D5)/12)),"0") -> 9.388601 | F11: Inventario final proyectado | G11: =G9+G10 -> 12121430 | H11: =H9+H10 -> 151
I14: Stock | L14: Tránsito Real | O14: Tránsito Proyectado | R14: Solicitud de compras | U14: Backlog | X14: Entregado a cliente (2026) | AA14: NEC | AD14: Presupuesto 2026 | AG14: Entregado últimos 12 meses | AK14: Pesco Producción
A15: # | B15: Código | C15: Origen | D15: Familia | E15: Subfamilia | F15: Descripción | G15: Sobre camión | H15: Código | I15: Costo unitario | J15: Stock | K15: Costo inventario | L15: Cantidad | M15: Costo unitario tránsito | N15: Costo tránsito | O15: Cantidad | P15: Costo unitario tránsito | Q15: Costo tránsito | R15: Cantidad solicitada | S15: Costo unitario solicitud | T15: Costo total solicitud | U15: Cantidad | V15: Precio de venta (u) | W15: Facturación total | X15: Cantidad | Y15: Precio de venta (u) | Z15: Total facturado | AA15: Cantidad | AB15: Precio de venta esperado (u) | AC15: Total proyectado | AD15: Cantidad | AE15: Precio de venta (u) | AF15: Total proyectado | AG15: Cantidad | AH15: Precio de venta (u) | AI15: Total facturado | AJ15: Margen venta | AK15: Cantidad | AL15: Costo unitario | AM15: Costo total
A16: 1 | B16: 70100247 | C16: Venta | D16: Hiab | E16: 1188 | F16: GRUA ARTICULADA HIAB IQ 1188 E-9 JIB | G16: No | H16: 70100247 | I16: 0 | J16: =IFERROR((VLOOKUP(B16,Stock!A:C,3,0)),"0") -> 0 | K16: =J16*I16 -> 0 | L16: =IFERROR((VLOOKUP(H16,Tránsito!A:C,3,0)),"0") -> 0 | M16: 0 | N16: =M16*L16 -> 0 | O16: =IFERROR((VLOOKUP(H16,Tránsito!A:D,4,0)),"0") -> 0 | P16: 0 | Q16: =P16*O16 -> 0 | S16: 0 | T16: =S16*R16 -> 0 | V16: 327000 | W16: =V16*U16 -> 0 | X16: =IFERROR((VLOOKUP(H16,'Entregado (2026)'!A:C,3,0)),"0") -> 0 | Y16: 0 | Z16: =Y16*X16 -> 0 | AB16: 331950 | AC16: =AB16*AA16 -> 0 | AD16: 4 | AE16: 377955 | AF16: =AE16*AD16 -> 1511820 | AG16: =IFERROR((VLOOKUP(H16,'Ventas (2025)'!A:C,3,0)),"0") -> 1 | AH16: 378014.06 | AI16: =AH16*AG16 -> 378014.06 | AM16: =AL16*AK16 -> 0
A17: 2 | B17: 13171051 | C17: Compra | D17: Hiab | E17: 1188 | F17: GRUA ARTICULADA HIAB IQ1188 E-9 JIB | G17: No | H17: 13171051 | I17: 252902.12 | J17: 1 | K17: =J17*I17 -> 252902.12 | L17: =IFERROR((VLOOKUP(H17,Tránsito!A:C,3,0)),"0") -> 0 | M17: 219745 | N17: =M17*L17 -> 0 | O17: =IFERROR((VLOOKUP(H17,Tránsito!A:D,4,0)),"0") -> 2 | P17: 218806.5 | Q17: =P17*O17 -> 437613 | S17: 285000 | T17: =S17*R17 -> 0 | U17: 2 | V17: 377910 | W17: =V17*U17 -> 755820 | X17: =IFERROR((VLOOKUP(H17,'Entregado (2026)'!A:C,3,0)),"0") -> 0 | Y17: 378014.06 | Z17: =Y17*X17 -> 0 | AB17: 280527 | AC17: =AB17*AA17 -> 0 | AE17: 350000 | AF17: =AE17*AD17 -> 0 | AG17: =IFERROR((VLOOKUP(H17,'Ventas (2025)'!A:C,3,0)),"0") -> 0 | AH17: 0 | AI17: =AH17*AG17 -> 0 | AM17: =AL17*AK17 -> 0
A18: 3 | B18: 13171068 | C18: Compra | D18: Hiab | E18: 1188 | F18: GRUA ARTICULADA HIAB IQ 1188 E-8 HIPRO EVO | G18: No | H18: 13171068 | I18: 175584.79 | J18: =IFERROR((VLOOKUP(B18,Stock!A:C,3,0)),"0") -> 4 | K18: =J18*I18 -> 702339.15 | L18: =IFERROR((VLOOKUP(H18,Tránsito!A:C,3,0)),"0") -> 1 | M18: 168375 | N18: =M18*L18 -> 168375 | O18: =IFERROR((VLOOKUP(H18,Tránsito!A:D,4,0)),"0") -> 2 | P18: 168374.74 | Q18: =P18*O18 -> 336749.48 | R18: 0 | S18: 66007.68 | T18: =S18*R18 -> 0 | W18: =V18*U18 -> 0 | X18: =IFERROR((VLOOKUP(H18,'Entregado (2026)'!A:C,3,0)),"0") -> 0 | Z18: =Y18*X18 -> 0 | AB18: 331950 | AC18: =AB18*AA18 -> 0 | AF18: =AE18*AD18 -> 0 | AG18: =IFERROR((VLOOKUP(H18,'Ventas (2025)'!A:C,3,0)),"0") -> 0 | AH18: 0 | AI18: =AH18*AG18 -> 0 | AM18: =AL18*AK18 -> 0
A19: 4 | B19: 13171055 | C19: Compra | D19: Hiab | E19: 1000 | F19: GRUA ARTICULADA EFFER 1000 9S TC JIB | G19: No | H19: 13171055 | I19: 221682.2 | J19: =IFERROR((VLOOKUP(B19,Stock!A:C,3,0)),"0") -> 0 | K19: =J19*I19 -> 0 | L19: =IFERROR((VLOOKUP(H19,Tránsito!A:C,3,0)),"0") -> 0 | M19: 0 | N19: =M19*L19 -> 0 | O19: =IFERROR((VLOOKUP(H19,Tránsito!A:D,4,0)),"0") -> 0 | P19: 0 | Q19: =P19*O19 -> 0 | S19: 0 | T19: =S19*R19 -> 0 | V19: 0 | W19: =V19*U19 -> 0 | X19: =IFERROR((VLOOKUP(H19,'Entregado (2026)'!A:C,3,0)),"0") -> 0 | Y19: 0 | Z19: =Y19*X19 -> 0 | AB19: =Y19 -> 0 | AC19: =AB19*AA19 -> 0 | AE19: 0 | AF19: =AE19*AD19 -> 0 | AG19: =IFERROR((VLOOKUP(H19,'Ventas (2025)'!A:C,3,0)),"0") -> 0 | AH19: 0 | AI19: =AH19*AG19 -> 0 | AM19: =AL19*AK19 -> 0
A20: 5 | B20: 79001005 | C20: Venta | D20: Hiab | E20: 1000 | F20: GRUA ARTICULADA EFFER 1000 9S TC JIB | G20: No | H20: 79001005 | I20: 0 | J20: =IFERROR((VLOOKUP(B20,Stock!A:C,3,0)),"0") -> 0 | K20: =J20*I20 -> 0 | L20: =IFERROR((VLOOKUP(H20,Tránsito!A:C,3,0)),"0") -> 0 | M20: 0 | N20: =M20*L20 -> 0 | O20: =IFERROR((VLOOKUP(H20,Tránsito!A:D,4,0)),"0") -> 0 | P20: 0 | Q20: =P20*O20 -> 0 | S20: 0 | T20: =S20*R20 -> 0 | V20: 0 | W20: =V20*U20 -> 0 | X20: =IFERROR((VLOOKUP(H20,'Entregado (2026)'!A:C,3,0)),"0") -> 0 | Y20: 0 | Z20: =Y20*X20 -> 0 | AB20: =Y20 -> 0 | AC20: =AB20*AA20 -> 0 | AE20: 374000 | AF20: =AE20*AD20 -> 0 | AG20: =IFERROR((VLOOKUP(H20,'Ventas (2025)'!A:C,3,0)),"0") -> 0 | AH20: 0 | AI20: =AH20*AG20 -> 0 | AM20: =AL20*AK20 -> 0
A21: 6 | B21: 79001006 | C21: Venta | D21: Hiab | E21: 1000 | F21: CAMION GRUA ARTICULADA EFFER 1000 9S TC JIB | G21: Sí | H21: 79001006 | J21: =IFERROR((VLOOKUP(B21,Stock!A:C,3,0)),"0") -> 0 | K21: =J21*I21 -> 0 | L21: =IFERROR((VLOOKUP(H21,Tránsito!A:C,3,0)),"0") -> 0 | N21: =M21*L21 -> 0 | O21: =IFERROR((VLOOKUP(H21,Tránsito!A:D,4,0)),"0") -> 0 | Q21: =P21*O21 -> 0 | T21: =S21*R21 -> 0 | W21: =V21*U21 -> 0 | X21: =IFERROR((VLOOKUP(H21,'Entregado (2026)'!A:C,3,0)),"0") -> 0 | Y21: 603967 | Z21: =Y21*X21 -> 0 | AC21: =AB21*AA21 -> 0 | AF21: =AE21*AD21 -> 0 | AG21: =IFERROR((VLOOKUP(H21,'Ventas (2025)'!A:C,3,0)),"0") -> 0 | AH21: 0 | AI21: =AH21*AG21 -> 0 | AM21: =AL21*AK21 -> 0
A22: 7 | B22: 70100221 | C22: Venta | D22: Hiab | E22: 858 | F22: GRUA ARTICULADA HIAB X-HIPRO 858 E-8 | G22: No | H22: 70100221 | I22: 0 | J22: =IFERROR((VLOOKUP(B22,Stock!A:C,3,0)),"0") -> 0 | K22: =J22*I22 -> 0 | L22: =IFERROR((VLOOKUP(H22,Tránsito!A:C,3,0)),"0") -> 0 | M22: 0 | N22: =M22*L22 -> 0 | O22: =IFERROR((VLOOKUP(H22,Tránsito!A:D,4,0)),"0") -> 0 | P22: 0 | Q22: =P22*O22 -> 0 | S22: 0 | T22: =S22*R22 -> 0 | V22: 247702 | W22: =V22*U22 -> 0 | X22: =IFERROR((VLOOKUP(H22,'Entregado (2026)'!A:C,3,0)),"0") -> 6 | Y22: =VLOOKUP(F22,'Entregado (2026)'!$B:$D,3,0) -> 224810.07 | Z22: =Y22*X22 -> 1348860.4 | AB22: 278950 | AC22: =AB22*AA22 -> 0 | AD22: 15 | AE22: 241037 | AF22: =AE22*AD22 -> 3615555 | AG22: =IFERROR((VLOOKUP(H22,'Ventas (2025)'!A:C,3,0)),"0") -> 9 | AH22: 246202.37 | AI22: =AH22*AG22 -> 2215821.4 | AM22: =AL22*AK22 -> 0
A23: 8 | B23: 13171012 | C23: Compra | D23: Hiab | E23: 858 | F23: GRUA ARTICULADA HIAB X-HIPRO 858 E-8 | G23: No | H23: 13171012 | I23: 153295 | J23: =IFERROR((VLOOKUP(B23,Stock!A:C,3,0)),"0") -> 1 | K23: =J23*I23 -> 153295 | L23: =IFERROR((VLOOKUP(H23,Tránsito!A:C,3,0)),"0") -> 4 | M23: 149145.03 | N23: =M23*L23 -> 596580.13 | O23: =IFERROR((VLOOKUP(H23,Tránsito!A:D,4,0)),"0") -> 2 | P23: 150280.8 | Q23: =P23*O23 -> 300561.6 | S23: 149145.03 | T23: =S23*R23 -> 0 | U23: 1 | V23: 217341 | W23: =V23*U23 -> 217341 | X23: =IFERROR((VLOOKUP(H23,'Entregado (2026)'!A:C,3,0)),"0") -> 0 | Y23: 228850 | Z23: =Y23*X23 -> 0 | AB23: 278950 | AC23: =AB23*AA23 -> 0 | AE23: 0 | AF23: =AE23*AD23 -> 0 | AG23: =IFERROR((VLOOKUP(H23,'Ventas (2025)'!A:C,3,0)),"0") -> 0 | AH23: 246202.37 | AI23: =AH23*AG23 -> 0 | AM23: =AL23*AK23 -> 0
A24: 9 | B24: 70100211 | C24: Venta | D24: Hiab | E24: 858 | F24: GRUA ARTICULADA HIAB X-HIPRO 858 E-10 | G24: No | H24: 70100211 | I24: 199611.5 | J24: =IFERROR((VLOOKUP(B24,Stock!A:C,3,0)),"0") -> 0 | K24: =J24*I24 -> 0 | L24: =IFERROR((VLOOKUP(H24,Tránsito!A:C,3,0)),"0") -> 0 | M24: 0 | N24: =M24*L24 -> 0 | O24: =IFERROR((VLOOKUP(H24,Tránsito!A:D,4,0)),"0") -> 0 | P24: 0 | Q24: =P24*O24 -> 0 | S24: 0 | T24: =S24*R24 -> 0 | V24: 0 | W24: =V24*U24 -> 0 | X24: =IFERROR((VLOOKUP(H24,'Entregado (2026)'!A:C,3,0)),"0") -> 0 | Y24: 259857.47 | Z24: =Y24*X24 -> 0 | AB24: =Y24 -> 259857.47 | AC24: =AB24*AA24 -> 0 | AE24: 0 | AF24: =AE24*AD24 -> 0 | AG24: =IFERROR((VLOOKUP(H24,'Ventas (2025)'!A:C,3,0)),"0") -> 1 | AH24: 266178.2 | AI24: =AH24*AG24 -> 266178.2 | AM24: =AL24*AK24 -> 0
A25: 10 | B25: 13171010 | C25: Compra | D25: Hiab | E25: 858 | F25: GRUA ARTICULADA HIAB X-HIPRO 858 E-8 JIB TC2 | G25: No | H25: 13171010 | J25: =IFERROR((VLOOKUP(B25,Stock!A:C,3,0)),"0") -> 0 | K25: =J25*I25 -> 0 | L25: =IFERROR((VLOOKUP(H25,Tránsito!A:C,3,0)),"0") -> 0 | N25: =M25*L25 -> 0 | O25: =IFERROR((VLOOKUP(H25,Tránsito!A:D,4,0)),"0") -> 0 | Q25: =P25*O25 -> 0 | S25: 0 | T25: =S25*R25 -> 0 | V25: 0 | W25: =V25*U25 -> 0 | X25: =IFERROR((VLOOKUP(H25,'Entregado (2026)'!A:C,3,0)),"0") -> 0 | Y25: 0 | Z25: =Y25*X25 -> 0 | AB25: 346700 | AC25: =AB25*AA25 -> 0 | AE25: 0 | AF25: =AE25*AD25 -> 0 | AG25: =IFERROR((VLOOKUP(H25,'Ventas (2025)'!A:C,3,0)),"0") -> 0 | AH25: 0 | AI25: =AH25*AG25 -> 0 | AM25: =AL25*AK25 -> 0
A26: 11 | B26: 13171070 | C26: Compra | D26: Hiab | E26: 708 | F26: HIAB iQ.708 HiPro E9 | G26: No | H26: 13171070 | J26: =IFERROR((VLOOKUP(B26,Stock!A:C,3,0)),"0") -> 0 | K26: =J26*I26 -> 0 | L26: =IFERROR((VLOOKUP(H26,Tránsito!A:C,3,0)),"0") -> 0 | N26: =M26*L26 -> 0 | O26: 2 | P26: 193901 | Q26: =P26*O26 -> 387802 | R26: 2 | S26: 142731 | T26: =S26*R26 -> 285462 | U26: 1 | V26: 626373 | W26: =V26*U26 -> 626373 | X26: =IFERROR((VLOOKUP(H26,'Entregado (2026)'!A:C,3,0)),"0") -> 0 | Z26: =Y26*X26 -> 0 | AC26: =AB26*AA26 -> 0 | AF26: =AE26*AD26 -> 0 | AG26: =IFERROR((VLOOKUP(H26,'Ventas (2025)'!A:C,3,0)),"0") -> 0 | AH26: 0 | AI26: =AH26*AG26 -> 0 | AM26: =AL26*AK26 -> 0
A27: 12 | B27: 70100213 | C27: Venta | D27: Hiab | E27: 638 | F27: CAMION GRUA ARTICULADA HIAB X-HIPRO 638 E-9 | G27: Sí | H27: 70100213 | I27: 0 | J27: =IFERROR((VLOOKUP(B27,Stock!A:C,3,0)),"0") -> 0 | K27: =J27*I27 -> 0 | L27: =IFERROR((VLOOKUP(H27,Tránsito!A:C,3,0)),"0") -> 0 | M27: 0 | N27: =M27*L27 -> 0 | O27: =IFERROR((VLOOKUP(H27,Tránsito!A:D,4,0)),"0") -> 0 | P27: 0 | Q27: =P27*O27 -> 0 | S27: 0 | T27: =S27*R27 -> 0 | V27: 0 | W27: =V27*U27 -> 0 | X27: =IFERROR((VLOOKUP(H27,'Entregado (2026)'!A:C,3,0)),"0") -> 0 | Y27: 399069.34 | Z27: =Y27*X27 -> 0 | AB27: =Y27 -> 399069.34 | AC27: =AB27*AA27 -> 0 | AE27: 0 | AF27: =AE27*AD27 -> 0 | AG27: =IFERROR((VLOOKUP(H27,'Ventas (2025)'!A:C,3,0)),"0") -> 0 | AH27: 399069.34 | AI27: =AH27*AG27 -> 0 | AM27: =AL27*AK27 -> 0
A28: 13 | B28: 13171033 | C28: Compra | D28: Hiab | E28: 638 | F28: GRUA ARTICULADA HIAB X-HIPRO 638 E-9 | G28: No | H28: 13171033 | I28: 149553.31 | J28: =IFERROR((VLOOKUP(B28,Stock!A:C,3,0)),"0") -> 2 | K28: =J28*I28 -> 299106.62 | L28: =IFERROR((VLOOKUP(H28,Tránsito!A:C,3,0)),"0") -> 5 | M28: 142589 | N28: =M28*L28 -> 712945 | O28: =IFERROR((VLOOKUP(H28,Tránsito!A:D,4,0)),"0") -> 0 | P28: 139566.3 | Q28: =P28*O28 -> 0 | S28: 125790 | T28: =S28*R28 -> 0 | V28: 222950 | W28: =V28*U28 -> 0 | X28: =IFERROR((VLOOKUP(H28,'Entregado (2026)'!A:C,3,0)),"0") -> 0 | Y28: =VLOOKUP(F28,'Entregado (2026)'!$B:$D,3,0) -> 210868.91 | Z28: =Y28*X28 -> 0 | AC28: =AB28*AA28 -> 0 | AE28: 0 | AF28: =AE28*AD28 -> 0 | AG28: =IFERROR((VLOOKUP(H28,'Ventas (2025)'!A:C,3,0)),"0") -> 0 | AH28: 188582.39 | AI28: =AH28*AG28 -> 0 | AM28: =AL28*AK28 -> 0
A29: 14 | B29: 70100212 | C29: Venta | D29: Hiab | E29: 638 | F29: GRUA ARTICULADA HIAB X-HIPRO 638 E-9 | G29: No | H29: 70100212 | I29: 142070 | J29: =IFERROR((VLOOKUP(B29,Stock!A:C,3,0)),"0") -> 0 | K29: =J29*I29 -> 0 | L29: =IFERROR((VLOOKUP(H29,Tránsito!A:C,3,0)),"0") -> 0 | M29: 144067.97 | N29: =M29*L29 -> 0 | O29: =IFERROR((VLOOKUP(H29,Tránsito!A:D,4,0)),"0") -> 0 | P29: 144067.97 | Q29: =P29*O29 -> 0 | S29: 0 | T29: =S29*R29 -> 0 | U29: 1 | V29: 221975 | W29: =V29*U29 -> 221975 | X29: 2 | Y29: 210869 | Z29: =Y29*X29 -> 421738 | AB29: 205800 | AC29: =AB29*AA29 -> 0 | AD29: 11 | AE29: 146637 | AF29: =AE29*AD29 -> 1613007 | AG29: 7 | AH29: 188582.39 | AI29: =AH29*AG29 -> 1320076.8 | AM29: =AL29*AK29 -> 0
A30: 15 | B30: 13171066 | C30: Compra | D30: Hiab | E30: 638 | F30: HIAB 638 EP9 (EVO) | G30: Sí | H30: 13171066 | I30: 141079.09 | J30: =IFERROR((VLOOKUP(B30,Stock!A:C,3,0)),"0") -> 2 | K30: =J30*I30 -> 282158.18 | L30: =IFERROR((VLOOKUP(H30,Tránsito!A:C,3,0)),"0") -> 0 | M30: 134799 | N30: =M30*L30 -> 0 | O30: =IFERROR((VLOOKUP(H30,Tránsito!A:D,4,0)),"0") -> 0 | P30: 134799 | Q30: =P30*O30 -> 0 | T30: =S30*R30 -> 0 | W30: =V30*U30 -> 0 | X30: =IFERROR((VLOOKUP(H30,'Entregado (2026)'!A:C,3,0)),"0") -> 0 | Z30: =Y30*X30 -> 0 | AC30: =AB30*AA30 -> 0 | AF30: =AE30*AD30 -> 0 | AG30: =IFERROR((VLOOKUP(H30,'Ventas (2025)'!A:C,3,0)),"0") -> 0 | AH30: 0 | AI30: =AH30*AG30 -> 0 | AM30: =AL30*AK30 -> 0
A31: 16 | B31: 70100206 | C31: Venta | D31: Hiab | E31: 558 | F31: GRUA ARTICULADA HIAB X-HIPRO 558 EP-5 | G31: No | H31: 70100206 | I31: 0 | J31: =IFERROR((VLOOKUP(B31,Stock!A:C,3,0)),"0") -> 0 | K31: =J31*I31 -> 0 | L31: =IFERROR((VLOOKUP(H31,Tránsito!A:C,3,0)),"0") -> 0 | M31: 0 | N31: =M31*L31 -> 0 | O31: =IFERROR((VLOOKUP(H31,Tránsito!A:D,4,0)),"0") -> 0 | P31: 0 | Q31: =P31*O31 -> 0 | S31: 0 | T31: =S31*R31 -> 0 | V31: 168305 | W31: =V31*U31 -> 0 | X31: =IFERROR((VLOOKUP(H31,'Entregado (2026)'!A:C,3,0)),"0") -> 0 | Y31: 163830.01 | Z31: =Y31*X31 -> 0 | AB31: 164973 | AC31: =AB31*AA31 -> 0 | AD31: 12 | AE31: 165036.67 | AF31: =AE31*AD31 -> 1980440 | AG31: =IFERROR((VLOOKUP(H31,'Ventas (2025)'!A:C,3,0)),"0") -> 11 | AH31: 164940.42 | AI31: =AH31*AG31 -> 1814344.6 | AM31: =AL31*AK31 -> 0
A32: 17 | B32: 70100275 | C32: Venta | D32: Hiab | E32: 558 | F32: GRUA ARTICULADA HIAB X HIPRO 558 EP6 | G32: No | H32: 70100275 | I32: 0 | J32: =IFERROR((VLOOKUP(B32,Stock!A:C,3,0)),"0") -> 0 | K32: =J32*I32 -> 0 | L32: =IFERROR((VLOOKUP(H32,Tránsito!A:C,3,0)),"0") -> 0 | M32: 0 | N32: =M32*L32 -> 0 | O32: =IFERROR((VLOOKUP(H32,Tránsito!A:D,4,0)),"0") -> 0 | P32: 0 | Q32: =P32*O32 -> 0 | S32: 0 | T32: =S32*R32 -> 0 | U32: 8 | V32: 154124.44 | W32: =V32*U32 -> 1232995.6 | X32: =IFERROR((VLOOKUP(H32,'Entregado (2026)'!A:C,3,0)),"0") -> 3 | Y32: 142061 | Z32: =Y32*X32 -> 426183 | AC32: =AB32*AA32 -> 0 | AD32: 2 | AE32: 168028 | AF32: =AE32*AD32 -> 336056 | AG32: =IFERROR((VLOOKUP(H32,'Ventas (2025)'!A:C,3,0)),"0") -> 6 | AH32: 171378.09 | AI32: =AH32*AG32 -> 1028268.5 | AM32: =AL32*AK32 -> 0
A33: 18 | B33: 19601024 | C33: Compra | D33: Hiab | E33: 558 | F33: HIAB X-HIPRO 558 EP-5 | G33: No | H33: 19601024 | I33: 99403.325 | J33: =IFERROR((VLOOKUP(B33,Stock!A:C,3,0)),"0") -> 1 | K33: =J33*I33 -> 99403.325 | L33: =IFERROR((VLOOKUP(H33,Tránsito!A:C,3,0)),"0") -> 0 | M33: 92527.325 | N33: =M33*L33 -> 0 | O33: =IFERROR((VLOOKUP(H33,Tránsito!A:D,4,0)),"0") -> 0 | P33: 92527.325 | Q33: =P33*O33 -> 0 | S33: 0 | T33: =S33*R33 -> 0 | U33: 1 | V33: 156912 | W33: =V33*U33 -> 156912 | X33: =IFERROR((VLOOKUP(H33,'Entregado (2026)'!A:C,3,0)),"0") -> 0 | Y33: 164096 | Z33: =Y33*X33 -> 0 | AB33: 184100 | AC33: =AB33*AA33 -> 0 | AE33: 0 | AF33: =AE33*AD33 -> 0 | AG33: =IFERROR((VLOOKUP(H33,'Ventas (2025)'!A:C,3,0)),"0") -> 0 | AH33: 0 | AI33: =AH33*AG33 -> 0 | AL33: 103870 | AM33: =AL33*AK33 -> 0
A34: 19 | B34: 19601036 | C34: Compra | D34: Hiab | E34: 558 | F34: HIAB X-HIPRO 558 EP-6 | G34: No | H34: 19601036 | I34: 107955 | J34: =IFERROR((VLOOKUP(B34,Stock!A:C,3,0)),"0") -> 0 | K34: =J34*I34 -> 0 | L34: =IFERROR((VLOOKUP(H34,Tránsito!A:C,3,0)),"0") -> 7 | M34: 107937.99 | N34: =M34*L34 -> 755565.92 | O34: =IFERROR((VLOOKUP(H34,Tránsito!A:D,4,0)),"0") -> 14 | P34: 107937.99 | Q34: =P34*O34 -> 1511131.8 | T34: =S34*R34 -> 0 | V34: 0 | W34: =V34*U34 -> 0 | X34: =IFERROR((VLOOKUP(H34,'Entregado (2026)'!A:C,3,0)),"0") -> 0 | Y34: 0 | Z34: =Y34*X34 -> 0 | AB34: 167500 | AC34: =AB34*AA34 -> 0 | AE34: 96540 | AF34: =AE34*AD34 -> 0 | AG34: =IFERROR((VLOOKUP(H34,'Ventas (2025)'!A:C,3,0)),"0") -> 0 | AH34: 0 | AI34: =AH34*AG34 -> 0 | AK34: 1 | AL34: 107955 | AM34: =AL34*AK34 -> 107955
A35: 20 | B35: 13171064 | C35: Compra | D35: Hiab | E35: 558 | F35: Hiab 558 EP5 - EVO | G35: No | H35: 13171064 | I35: 122572 | J35: =IFERROR((VLOOKUP(B35,Stock!A:C,3,0)),"0") -> 1 | K35: =J35*I35 -> 122572 | L35: =IFERROR((VLOOKUP(H35,Tránsito!A:C,3,0)),"0") -> 0 | M35: 250168 | N35: =M35*L35 -> 0 | O35: =IFERROR((VLOOKUP(H35,Tránsito!A:D,4,0)),"0") -> 0 | P35: 250168 | Q35: =P35*O35 -> 0 | S35: 119948 | T35: =S35*R35 -> 0 | V35: 0 | W35: =V35*U35 -> 0 | X35: =IFERROR((VLOOKUP(H35,'Entregado (2026)'!A:C,3,0)),"0") -> 0 | Y35: 0 | Z35: =Y35*X35 -> 0 | AC35: =AB35*AA35 -> 0 | AE35: 0 | AF35: =AE35*AD35 -> 0 | AG35: =IFERROR((VLOOKUP(H35,'Ventas (2025)'!A:C,3,0)),"0") -> 0 | AH35: 0 | AI35: =AH35*AG35 -> 0 | AK35: 7 | AL35: 122572 | AM35: =AL35*AK35 -> 858004
A36: 21 | B36: 70100174 | C36: Venta | D36: Hiab | E36: 558 | F36: CAMION GRUA ARTICULADA HIAB X-HIPRO 558 EP-5 | G36: Sí | H36: 70100174 | J36: =IFERROR((VLOOKUP(B36,Stock!A:C,3,0)),"0") -> 0 | K36: =J36*I36 -> 0 | L36: =IFERROR((VLOOKUP(H36,Tránsito!A:C,3,0)),"0") -> 0 | N36: =M36*L36 -> 0 | O36: =IFERROR((VLOOKUP(H36,Tránsito!A:D,4,0)),"0") -> 0 | Q36: =P36*O36 -> 0 | T36: =S36*R36 -> 0 | V36: 382998 | W36: =V36*U36 -> 0 | X36: =IFERROR((VLOOKUP(H36,'Entregado (2026)'!A:C,3,0)),"0") -> 0 | Y36: 337868 | Z36: =Y36*X36 -> 0 | AB36: 378690 | AC36: =AB36*AA36 -> 0 | AF36: =AE36*AD36 -> 0 | AG36: 2 | AH36: 337867.94 | AI36: =AH36*AG36 -> 675735.88 | AM36: =AL36*AK36 -> 0
A37: 22 | B37: 70100160 | C37: Compra | D37: Hiab | E37: 558 | F37: GRUA ARTICULADA HIAB X-HIPRO 558 EP-6 EVO | G37: No | H37: 70100160 | J37: =IFERROR((VLOOKUP(B37,Stock!A:C,3,0)),"0") -> 0 | K37: =J37*I37 -> 0 | L37: =IFERROR((VLOOKUP(H37,Tránsito!A:C,3,0)),"0") -> 0 | N37: =M37*L37 -> 0 | O37: =IFERROR((VLOOKUP(H37,Tránsito!A:D,4,0)),"0") -> 0 | Q37: =P37*O37 -> 0 | T37: =S37*R37 -> 0 | U37: 7 | V37: 149080 | W37: =V37*U37 -> 1043560 | X37: 3 | Y37: 145230.16 | Z37: =Y37*X37 -> 435690.47 | AC37: =AB37*AA37 -> 0 | AF37: =AE37*AD37 -> 0 | AG37: 3 | AH37: 0 | AI37: =AH37*AG37 -> 0 | AM37: =AL37*AK37 -> 0
A38: 23 | B38: 70100205 | C38: Venta | D38: Hiab | E38: 548 | F38: GRUA ARTICULADA HIAB X-HIPRO 548 E-9 | G38: No | H38: 70100205 | I38: 0 | J38: =IFERROR((VLOOKUP(B38,Stock!A:C,3,0)),"0") -> 0 | K38: =J38*I38 -> 0 | L38: =IFERROR((VLOOKUP(H38,Tránsito!A:C,3,0)),"0") -> 0 | M38: 0 | N38: =M38*L38 -> 0 | O38: =IFERROR((VLOOKUP(H38,Tránsito!A:D,4,0)),"0") -> 0 | P38: 0 | Q38: =P38*O38 -> 0 | S38: 103280 | T38: =S38*R38 -> 0 | U38: 2 | V38: 189089.33 | W38: =V38*U38 -> 378178.67 | X38: 1 | Y38: 189673.53 | Z38: =Y38*X38 -> 189673.53 | AB38: 276714.2 | AC38: =AB38*AA38 -> 0 | AD38: 8 | AE38: 186837 | AF38: =AE38*AD38 -> 1494696 | AG38: 3 | AH38: 189737.42 | AI38: =AH38*AG38 -> 569212.27 | AM38: =AL38*AK38 -> 0
A39: 24 | B39: 70901020 | C39: Venta | D39: Hiab | E39: 548 | F39: CAMION GRUA ARTICULADA HIAB X-HIPRO 548 E-9 | G39: Sí | H39: 70901020 | I39: 0 | J39: =IFERROR((VLOOKUP(B39,Stock!A:C,3,0)),"0") -> 0 | K39: =J39*I39 -> 0 | L39: =IFERROR((VLOOKUP(H39,Tránsito!A:C,3,0)),"0") -> 0 | M39: 0 | N39: =M39*L39 -> 0 | O39: =IFERROR((VLOOKUP(H39,Tránsito!A:D,4,0)),"0") -> 0 | P39: 0 | Q39: =P39*O39 -> 0 | S39: 0 | T39: =S39*R39 -> 0 | V39: 0 | W39: =V39*U39 -> 0 | X39: =IFERROR((VLOOKUP(H39,'Entregado (2026)'!A:C,3,0)),"0") -> 0 | Y39: 187791.67 | Z39: =Y39*X39 -> 0 | AB39: =Y39 -> 187791.67 | AC39: =AB39*AA39 -> 0 | AE39: 0 | AF39: =AE39*AD39 -> 0 | AG39: =IFERROR((VLOOKUP(H39,'Ventas (2025)'!A:C,3,0)),"0") -> 0 | AH39: 187791.67 | AI39: =AH39*AG39 -> 0 | AM39: =AL39*AK39 -> 0
A40: 25 | B40: 19502062 | C40: Compra | D40: Hiab | E40: 548 | F40: GRUA ARTICULADA HIAB X-HIPRO 548 E-9 año 2022 | G40: No | H40: 19502062 | I40: 145127.51 | J40: =IFERROR((VLOOKUP(B40,Stock!A:C,3,0)),"0") -> 1 | K40: =J40*I40 -> 145127.51 | L40: =IFERROR((VLOOKUP(H40,Tránsito!A:C,3,0)),"0") -> 0 | M40: 0 | N40: =M40*L40 -> 0 | O40: =IFERROR((VLOOKUP(H40,Tránsito!A:D,4,0)),"0") -> 0 | P40: 0 | Q40: =P40*O40 -> 0 | S40: 0 | T40: =S40*R40 -> 0 | V40: 191500 | W40: =V40*U40 -> 0 | X40: 2 | Y40: 47218.939 | Z40: =Y40*X40 -> 94437.878 | AB40: =Y40 -> 47218.939 | AC40: =AB40*AA40 -> 0 | AE40: 0 | AF40: =AE40*AD40 -> 0 | AG40: =IFERROR((VLOOKUP(H40,'Ventas (2025)'!A:C,3,0)),"0") -> 1 | AH40: 140506.63 | AI40: =AH40*AG40 -> 140506.63 | AM40: =AL40*AK40 -> 0
A41: 26 | B41: 19502041 | C41: Compra | D41: Hiab | E41: 548 | F41: HIAB X-HIPRO 548 E-9 | G41: No | H41: 19502041 | I41: 120585 | J41: 3 | K41: =J41*I41 -> 361755 | L41: =IFERROR((VLOOKUP(H41,Tránsito!A:C,3,0)),"0") -> 4 | M41: 121896.14 | N41: =M41*L41 -> 487584.55 | O41: =IFERROR((VLOOKUP(H41,Tránsito!A:D,4,0)),"0") -> 0 | P41: 121896.14 | Q41: =P41*O41 -> 0 | R41: 4 | S41: 104123.52 | T41: =S41*R41 -> 416494.08 | V41: 0 | W41: =V41*U41 -> 0 | X41: =IFERROR((VLOOKUP(H41,'Entregado (2026)'!A:C,3,0)),"0") -> 0 | Y41: 0 | Z41: =Y41*X41 -> 0 | AB41: 222000 | AC41: =AB41*AA41 -> 0 | AE41: 221581 | AF41: =AE41*AD41 -> 0 | AG41: =IFERROR((VLOOKUP(H41,'Ventas (2025)'!A:C,3,0)),"0") -> 0 | AH41: 0 | AI41: =AH41*AG41 -> 0 | AM41: =AL41*AK41 -> 0
A42: 27 | D42: Hiab | E42: 548 | F42: HIAB X-HIPRO 548 E8 JIB 150X6 | G42: No | J42: =IFERROR((VLOOKUP(B42,Stock!A:C,3,0)),"0") -> 0 | L42: =IFERROR((VLOOKUP(H42,Tránsito!A:C,3,0)),"0") -> 0 | N42: =M42*L42 -> 0 | O42: =IFERROR((VLOOKUP(H42,Tránsito!A:D,4,0)),"0") -> 0 | Q42: =P42*O42 -> 0 | X42: =IFERROR((VLOOKUP(H42,'Entregado (2026)'!A:C,3,0)),"0") -> 0 | Z42: =Y42*X42 -> 0 | AB42: 238000 | AC42: =AB42*AA42 -> 0 | AG42: =IFERROR((VLOOKUP(H42,'Ventas (2025)'!A:C,3,0)),"0") -> 0 | AH42: 0 | AI42: =AH42*AG42 -> 0 | AM42: =AL42*AK42 -> 0
A43: 28 | B43: 13171065 | C43: Compra | D43: Hiab | E43: 548 | F43: HIAB 548 EP 9 (EVO) | G43: Sí | H43: 13171065 | I43: 118916.29 | J43: =IFERROR((VLOOKUP(B43,Stock!A:C,3,0)),"0") -> 2 | K43: =J43*I43 -> 237832.58 | L43: =IFERROR((VLOOKUP(H43,Tránsito!A:C,3,0)),"0") -> 0 | M43: 120467 | N43: =M43*L43 -> 0 | O43: =IFERROR((VLOOKUP(H43,Tránsito!A:D,4,0)),"0") -> 0 | P43: 120467 | Q43: =P43*O43 -> 0 | T43: =S43*R43 -> 0 | W43: =V43*U43 -> 0 | X43: =IFERROR((VLOOKUP(H43,'Entregado (2026)'!A:C,3,0)),"0") -> 0 | Z43: =Y43*X43 -> 0 | AC43: =AB43*AA43 -> 0 | AF43: =AE43*AD43 -> 0 | AG43: =IFERROR((VLOOKUP(H43,'Ventas (2025)'!A:C,3,0)),"0") -> 0 | AH43: 0 | AI43: =AH43*AG43 -> 0 | AM43: =AL43*AK43 -> 0
...

Sheet Glosario códigos
A4: # | B4: Código | C4: Origen | D4: Familia | E4: Subfamilia | F4: Descripción | G4: Sobre camión | H4: Código | I4: Subfamilia
A5: 1 | B5: 13171051 | C5: Compra | D5: Hiab | E5: 1188 | F5: GRUA ARTICULADA HIAB IQ 1188 E-9 JIB | G5: No | H5: 13171051 | I5: 1188
A6: 2 | B6: 70100247 | C6: Venta | D6: Hiab | E6: 1188 | F6: GRUA ARTICULADA HIAB IQ 1188 E-9 JIB | G6: No | H6: 70100247 | I6: 1188
A7: 3 | B7: 13171068 | C7: Compra | D7: Hiab | E7: 1188 | F7: GRUA ARTICULADA HIAB IQ 1188 E-8 HIPRO EVO | G7: No | H7: 13171068 | I7: 1188
A8: 4 | B8: 79001005 | C8: Venta | D8: Effer | E8: 1000 | F8: GRUA ARTICULADA EFFER 1000 9S TC JIB | G8: No | H8: 79001005 | I8: 1000
A9: 5 | B9: 13171055 | C9: Compra | D9: Effer | E9: 1000 | F9: GRUA ARTICULADA EFFER 1000 9S TC JIB | G9: No | H9: 13171055 | I9: 1000
A10: 6 | B10: 79001006 | C10: Venta | D10: Hiab | E10: 1000 | F10: CAMION GRUA ARTICULADA EFFER 1000 9S TC JIB | G10: Sí | H10: 79001006 | I10: 1000
A11: 7 | B11: 13171012 | C11: Compra | D11: Hiab | E11: 858 | F11: GRUA ARTICULADA HIAB X-HIPRO 858 E-8 | G11: No | H11: 13171012 | I11: 858
A12: 8 | B12: 70100211 | C12: Venta | D12: Hiab | E12: 858 | F12: GRUA ARTICULADA HIAB X-HIPRO 858 E-10 | G12: No | H12: 70100211 | I12: 858
A13: 9 | B13: 70100221 | C13: Venta | D13: Hiab | E13: 858 | F13: GRUA ARTICULADA HIAB X-HIPRO 858 E-8 | G13: No | H13: 70100221 | I13: 858
A14: 10 | B14: 70100212 | C14: Venta | D14: Hiab | E14: 638 | F14: GRUA ARTICULADA HIAB X-HIPRO 638 E-9 | G14: No | H14: 70100212 | I14: 638
A15: 11 | B15: 13171033 | C15: Compra | D15: Hiab | E15: 638 | F15: GRUA ARTICULADA HIAB X-HIPRO 638 E-9 | G15: No | H15: 13171033 | I15: 638
A16: 12 | B16: 70100213 | C16: Venta | D16: Hiab | E16: 638 | F16: CAMION GRUA ARTICULADA HIAB X-HIPRO 638 E-9 | G16: Sí | H16: 70100213 | I16: 638
A17: 13 | B17: 13171066 | C17: Compra | D17: Hiab | E17: 638 | F17: HIAB 638 EP9 (EVO) | G17: No | H17: 13171066 | I17: 638
A18: 14 | B18: 19601036 | C18: Compra | D18: Hiab | E18: 558 | F18: GRUA ARTICULADA HIAB X-HIPRO 558 EP-6 | G18: No | H18: 19601036 | I18: 558
A19: 15 | B19: 19601024 | C19: Compra | D19: Hiab | E19: 558 | F19: GRUA ARTICULADA HIAB X-HIPRO 558 EP-5 | G19: No | H19: 19601024 | I19: 558
A20: 16 | B20: 70100206 | C20: Venta | D20: Hiab | E20: 558 | F20: GRUA ARTICULADA HIAB X-HIPRO 558 EP-5 | G20: No | H20: 70100206 | I20: 558
A21: 17 | B21: 70100275 | C21: Venta | D21: Hiab | E21: 558 | F21: GRUA ARTICULADA HIAB X HIPRO 558 EP6 | G21: No | H21: 70100275 | I21: 558
A22: 18 | B22: 13171064 | C22: Compra | D22: Hiab | E22: 558 | F22: Hiab 558 EP5 - EVO | G22: No | H22: 13171064 | I22: 558
A23: 19 | C23: Venta | D23: Hiab | E23: 558 | F23: CAMION GRUA ARTICULADA HIAB X-HIPRO 558 EP-5 | G23: Sí | I23: 558
A24: 20 | B24: 70901020 | C24: Venta | D24: Hiab | E24: 548 | F24: CAMION GRUA ARTICULADA HIAB X-HIPRO 548 E-9 | G24: Sí | H24: 70901020 | I24: 548
A25: 21 | B25: 70100205 | C25: Venta | D25: Hiab | E25: 548 | F25: GRUA ARTICULADA HIAB X-HIPRO 548 E-9 | G25: No | H25: 70100205 | I25: 548
A26: 22 | B26: 19502041 | C26: Compra | D26: Hiab | E26: 548 | F26: HIAB X-HIPRO 548 E-9 | G26: No | H26: 19502041 | I26: 548
A27: 23 | B27: 19502062 | C27: Compra | D27: Hiab | E27: 548 | F27: GRUA ARTICULADA HIAB X-HIPRO 548 E-9 año 2022 | G27: No | H27: 19502062 | I27: 548
A28: 24 | B28: 13171065 | C28: Compra | D28: Hiab | E28: 548 | F28: HIAB 548 EP 9 (EVO) | G28: No | H28: 13171065 | I28: 548
A29: 25 | B29: 13171022 | C29: Compra | D29: Hiab | E29: 418 | F29: HIAB X-HIPRO 418 EP-5 | G29: No | H29: 13171022 | I29: 418
A30: 26 | B30: 70100165 | C30: Venta | D30: Hiab | E30: 418 | F30: GRUA ARTICULADA HIAB X-HIPRO 418 EP-5 | G30: No | H30: 70100165 | I30: 418
A31: 27 | B31: 70100173 | C31: Venta | D31: Hiab | E31: 418 | F31: CAMION GRUA ARTICULADA HIAB X-HIPRO 418 EP-5 | G31: Sí | H31: 70100173 | I31: 418
A32: 28 | B32: 70100164 | C32: Venta | D32: Hiab | E32: 408 | F32: GRUA ARTICULADA HIAB X-HIPRO 408 E-8 | G32: No | H32: 70100164 | I32: 408
A33: 29 | B33: 13171021 | C33: Compra | D33: Hiab | E33: 408 | F33: HIAB X-HIPRO 408 E-8 | G33: No | H33: 13171021 | I33: 408
A34: 30 | C34: Venta | D34: Hiab | E34: 408 | F34: CAMION GRUA HIAB X-HIPRO 408 E8 | G34: Sí | I34: 408
A35: 31 | C35: Venta | D35: Hiab | E35: 408 | F35: GRUA ARTICULADA HIAB X-HIPRO 408 E-8 + MULTILIFT OPTIMA 20S | G35: No | I35: 408
A36: 32 | B36: 10705003 | C36: Compra | D36: Hiab | E36: 388 | F36: GRUA HIAB X-CLX 388 EP5 | G36: No | H36: 10705003 | I36: 388
A37: 33 | B37: 70100253 | C37: Venta | D37: Hiab | E37: 388 | F37: GRUA HIAB X-CLX 388 EP5 | G37: No | H37: 70100253 | I37: 388
A38: 34 | B38: 70901021 | C38: Venta | D38: Hiab | E38: 362 | F38: CAMION GRUA ARTICULADA HIAB X-HIPRO 362 EP-5 | G38: Sí | H38: 70901021 | I38: 362
A39: 35 | B39: 13171020 | C39: Compra | D39: Hiab | E39: 362 | F39: GRUA ARTICULADA HIAB X-HIPRO 362 EP-5 | G39: No | H39: 13171020 | I39: 362
A40: 36 | B40: 70100171 | C40: Venta | D40: Hiab | E40: 362 | F40: GRUA ARTICULADA HIAB X-HIPRO 362 EP-5 | G40: No | H40: 70100171 | I40: 362
A41: 37 | B41: 13171063 | C41: Compra | D41: Hiab | E41: 362 | F41: Hiab 362 EP5 - EVO | G41: No | H41: 13171063 | I41: 362
A42: 38 | B42: 13171067 | C42: Compra | D42: Hiab | E42: 355 | F42: GRUA ARTICULADA EFFER IX 355 E-8 HIPRO | G42: No | H42: 13171067 | I42: 355
A43: 39 | B43: 70100222 | C43: Venta | D43: Hiab | E43: 352 | F43: GRUA ARTICULADA HIAB X-HIPRO 352 E-6 | G43: No | H43: 70100222 | I43: 352
...

Sheet Flujo de caja
C3: Flujo de caja consolidado:
C4: Categoría | D4: Enero | E4: Febrero | F4: Marzo | G4: Abril | H4: Mayo | I4: Junio | J4: Julio | K4: Agosto | L4: Septiembre | M4: Octubre | N4: Noviembre | O4: Diciembre | P4: Total
C5: Compra | D5: 0 | E5: 0 | F5: 0 | G5: 0 | H5: 0 | I5: 0 | J5: 0 | K5: 0 | L5: 0 | M5: 0 | N5: 0 | O5: 0 | P5: =SUM(D5:O5) -> 0
C6: Venta | D6: 0 | E6: 0 | F6: 0 | G6: 0 | H6: 0 | I6: 0 | J6: 0 | K6: 0 | L6: 0 | M6: 0 | N6: 0 | O6: 0 | P6: =SUM(D6:O6) -> 0
C7: Flete | D7: 0 | E7: 0 | F7: 0 | G7: 0 | H7: 0 | I7: 0 | J7: 0 | K7: 0 | L7: 0 | M7: 0 | N7: 0 | O7: 0 | P7: =SUM(D7:O7) -> 0
C8: *Considerar mes 2 | P8: =P6-P5-P7 -> 0
B11: 1) | C11: Subfamilia: | D11: 1188
C12: Familia: | D12: Hiab
C13: Categoría | D13: Enero | E13: Febrero | F13: Marzo | G13: Abril | H13: Mayo | I13: Junio | J13: Julio | K13: Agosto | L13: Septiembre | M13: Octubre | N13: Noviembre | O13: Diciembre | P13: Total
C14: Compra | D14: 0 | E14: 0 | F14: 0 | G14: 0 | H14: 0 | I14: 0 | J14: 0 | K14: 0 | L14: 0 | M14: 0 | N14: 0 | O14: 0 | P14: =SUM(D14:O14) -> 0
C15: Venta | D15: 0 | E15: 0 | F15: 0 | G15: 0 | H15: 0 | I15: 0 | J15: 0 | K15: 0 | L15: 0 | M15: 0 | N15: 0 | O15: 0 | P15: =SUM(D15:O15) -> 0
C16: Flete | D16: 0 | E16: 0 | F16: 0 | G16: 0 | H16: 0 | I16: 0 | J16: 0 | K16: 0 | L16: 0 | M16: 0 | N16: 0 | O16: 0 | P16: =SUM(D16:O16) -> 0
P17: =P15-P14-P16 -> 0
B19: 2) | C19: Subfamilia: | D19: 1000
C20: Marca: | D20: Effer
C21: Categoría | D21: Enero | E21: Febrero | F21: Marzo | G21: Abril | H21: Mayo | I21: Junio | J21: Julio | K21: Agosto | L21: Septiembre | M21: Octubre | N21: Noviembre | O21: Diciembre | P21: Total
C22: Compra | D22: 0 | E22: 0 | F22: 0 | G22: 0 | H22: 0 | I22: 0 | J22: 0 | K22: 0 | L22: 0 | M22: 0 | N22: 0 | O22: 0 | P22: =SUM(D22:O22) -> 0
C23: Venta | D23: 0 | E23: 0 | F23: 0 | G23: 0 | H23: 0 | I23: 0 | J23: 0 | K23: 0 | L23: 0 | M23: 0 | N23: 0 | O23: 0 | P23: =SUM(D23:O23) -> 0
C24: Flete | D24: 0 | E24: 0 | F24: 0 | G24: 0 | H24: 0 | I24: 0 | J24: 0 | K24: 0 | L24: 0 | M24: 0 | N24: 0 | O24: 0 | P24: =SUM(D24:O24) -> 0
P25: =P23-P22-P24 -> 0
B27: 3) | C27: Subfamilia: | D27: 858
C28: Marca: | D28: Hiab
C29: Categoría | D29: Enero | E29: Febrero | F29: Marzo | G29: Abril | H29: Mayo | I29: Junio | J29: Julio | K29: Agosto | L29: Septiembre | M29: Octubre | N29: Noviembre | O29: Diciembre | P29: Total
C30: Compra | D30: 0 | E30: 0 | F30: 0 | G30: 0 | H30: 0 | I30: 0 | J30: 0 | K30: 0 | L30: 0 | M30: 0 | N30: 0 | O30: 0 | P30: =SUM(D30:O30) -> 0
C31: Venta | D31: 0 | E31: 0 | F31: 0 | G31: 0 | H31: 0 | I31: 0 | J31: 0 | K31: 0 | L31: 0 | M31: 0 | N31: 0 | O31: 0 | P31: =SUM(D31:O31) -> 0
C32: Flete | D32: 0 | E32: 0 | F32: 0 | G32: 0 | H32: 0 | I32: 0 | J32: 0 | K32: 0 | L32: 0 | M32: 0 | N32: 0 | O32: 0 | P32: =SUM(D32:O32) -> 0
P33: =P31-P30-P32 -> 0
B35: 4) | C35: Subfamilia: | D35: 638
C36: Marca: | D36: Hiab
C37: Categoría | D37: Enero | E37: Febrero | F37: Marzo | G37: Abril | H37: Mayo | I37: Junio | J37: Julio | K37: Agosto | L37: Septiembre | M37: Octubre | N37: Noviembre | O37: Diciembre | P37: Total
C38: Compra | D38: 0 | E38: 0 | F38: 0 | G38: 0 | H38: 0 | I38: 0 | J38: 0 | K38: 0 | L38: 0 | M38: 0 | N38: 0 | O38: 0 | P38: =SUM(D38:O38) -> 0
C39: Venta | D39: 0 | E39: 0 | F39: 0 | G39: 0 | H39: 0 | I39: 0 | J39: 0 | K39: 0 | L39: 0 | M39: 0 | N39: 0 | O39: 0 | P39: =SUM(D39:O39) -> 0
C40: Flete | D40: 0 | E40: 0 | F40: 0 | G40: 0 | H40: 0 | I40: 0 | J40: 0 | K40: 0 | L40: 0 | M40: 0 | N40: 0 | O40: 0 | P40: =SUM(D40:O40) -> 0
P41: =P39-P38-P40 -> 0
B43: 5) | C43: Subfamilia: | D43: 558
C44: Marca: | D44: Hiab
C45: Categoría | D45: Enero | E45: Febrero | F45: Marzo | G45: Abril | H45: Mayo | I45: Junio | J45: Julio | K45: Agosto | L45: Septiembre | M45: Octubre | N45: Noviembre | O45: Diciembre | P45: Total
C46: Compra | D46: 0 | E46: 0 | F46: 0 | G46: 0 | H46: 0 | I46: 0 | J46: 0 | K46: 0 | L46: 0 | M46: 0 | N46: 0 | O46: 0 | P46: =SUM(D46:O46) -> 0
C47: Venta | D47: 0 | E47: 0 | F47: 0 | G47: 0 | H47: 0 | I47: 0 | J47: 0 | K47: 0 | L47: 0 | M47: 0 | N47: 0 | O47: 0 | P47: =SUM(D47:O47) -> 0
C48: Flete | D48: 0 | E48: 0 | F48: 0 | G48: 0 | H48: 0 | I48: 0 | J48: 0 | K48: 0 | L48: 0 | M48: 0 | N48: 0 | O48: 0 | P48: =SUM(D48:O48) -> 0
...

Sheet Solicitud de compra
B2: Proveedor | C2: Código compra | D2: Descripción | E2: Cantidad | F2: % | G2: Costo unitario | H2: costo total
B3: HIAB | C3: 13171020 | D3: HIAB X-HIPRO 362 EP-5 | E3: 6 | F3: 0.08 | G3: 66007.68 | H3: =G3*E3 -> 396046.08
B4: HIAB | C4: 13171021 | D4: HIAB X-HIPRO 408 E-8 | E4: 4 | F4: 0.09 | G4: 88544.64 | H4: =G4*E4 -> 354178.56
B5: HIAB | C5: 13171022 | D5: HIAB X-HIPRO 418 EP-5 | E5: 4 | F5: 0.1 | G5: 154207.68 | H5: =G5*E5 -> 616830.72
B6: HIAB | C6: 19502041 | D6: HIAB X-HIPRO 548 E9 | E6: 4 | F6: 0.08 | G6: 104123.52 | H6: =G6*E6 -> 416494.08
B7: HIAB | C7: 13171070 | D7: HIAB iQ.708 HiPro E9 | E7: 2 | F7: 0.09 | G7: 142731 | H7: =G7*E7 -> 285462
G8: Total | H8: =SUM(H3:H7) -> 2069011.4

Sheet Ventas (2025)
A1: Código | B1: Descripción | C1: Cantidad | D1: Precio unitario | E1: Facturación total | F1: Margen bruto promedio | H1: Año | I1: NroMes | J1: Proyecto | K1: NombreProyecto | L1: NombreAreaNegocio | M1: NombreCentroCosto | N1: NombreLineaNegocio | O1: NombreSubLineaNegocio | P1: Vendedor | Q1: Venta Real ML | R1: Costo Real ML | S1: Margen Bruto Real ML | T1: Margen Bruto Real ML (%) | U1: CodArticulo | V1: Last DescripcionArticuloMayor | W1: Last NombreUsuario | X1: TipoCosto | Y1: Last Glosa | Z1: Max of NroAsiento | AA1: Latest FechaActualizacion | AB1: NombreClienteFinalBI | AC1: GuiaAdjunta | AD1: Rut | AE1: CodArticulo | AF1: CodArticulo | AI1: CodArticulo | AJ1: Last DescripcionArticuloMayor
A2: 70100211 | B2: GRUA ARTICULADA HIAB X-HIPRO 858 E-10 | C2: =COUNTIF(U:U,A2) -> 1 | D2: 266178.2 | E2: =D2*C2 -> 266178.2 | F2: =AVERAGEIF(U:U,A2,T:T) -> 0.2500832 | H2: 2025 | I2: 9 | J2: 2503036 | K2: SISTEMA DE TRANSMISION DEL NORTE S.A | L2: COMERCIAL ZONA CENTRO | M2: IZAJE | P2: FRANCO MODINGER | Q2: 345.05943 | R2: -240.99951 | S2: 104.05991 | T2: 0.301571 | U2: 79001011 | V2: CAMION GRUA HIAB 352 E8 X-HIPRO | W2: Estrella Rodriguez | X2: 1-PROYECTO COMERCIAL | Y2: Facturas clientes - 76410374C | Z2: 417038 | AA2: 45929 | AB2: SISTEMA DE TRANSMISION DEL NORTE S.A | AC2: 74389 | AD2: 96572360-9 | AE2: 70100211 | AF2: 70100211 | AI2: 70100211 | AJ2: GRUA ARTICULADA HIAB X-HIPRO 858 E-10
A3: 79001011 | B3: CAMION GRUA HIAB 352 E8 X-HIPRO | C3: =COUNTIF(U:U,A3) -> 1 | D3: 345059.43 | E3: =D3*C3 -> 345059.43 | F3: =AVERAGEIF(U:U,A3,T:T) -> 0.301571 | H3: 2026 | I3: 2 | J3: 2602197 | K3: SOC COMERCIAL E INDUSTRIAL JOMAR LIMITADA | L3: CANAL PROPIO | M3: IZAJE | O3: ZONA SUR - PTO MONTT | P3: EDUARDO OÑATE | Q3: 25.586496 | R3: -19.504933 | S3: 6.0815631 | T3: 0.23768644 | U3: 70100294 | V3: GRUA HIAB CL 16 B-3 MARINA | W3: Estrella Rodriguez | X3: 1-PROYECTO COMERCIAL | Y3: Facturas clientes - 76263360C | Z3: 485855 | AA3: 46079 | AB3: SOC COMERCIAL E INDUSTRIAL JOMAR LIMITADA | AC3: 86182 | AD3: 76410374-2 | AE3: 79001011 | AF3: 79001011 | AI3: 79001011 | AJ3: CAMION GRUA HIAB 352 E8 X-HIPRO
A4: 70100170 | B4: CAMION GRUA ARTICULADA HIAB X-HIDUO 258 EP-5 | C4: =COUNTIF(U:U,A4) -> 2 | D4: 183545.42 | E4: =D4*C4 -> 367090.85 | F4: =AVERAGEIF(U:U,A4,T:T) -> 0.13728171 | H4: 2026 | I4: 4 | J4: 2604201 | K4: GERMAN ROBINSON GUERRERO AYANCAN | L4: CANAL PROPIO | M4: IZAJE | P4: EDUARDO OÑATE | Q4: 25.774664 | R4: -18.582324 | S4: 7.19234 | T4: 0.2790469 | U4: 70100294 | V4: GRUA HIAB CL 16 B-3 MARINA | W4: Estrella Rodriguez | X4: 1-PROYECTO COMERCIAL | Y4: Orden fabricación: 70100294 | Z4: 508539 | AA4: 46128 | AB4: GERMAN ROBINSON GUERRERO AYANCAN | AC4: 91861 | AD4: 61106000-9 | AE4: 70100170 | AF4: 70100170 | AI4: 70100170 | AJ4: CAMION GRUA ARTICULADA HIAB X-HIDUO 258 EP-5
A5: 70100206 | B5: GRUA ARTICULADA HIAB X-HIPRO 558 EP-5 | C5: =COUNTIF(U:U,A5) -> 11 | D5: 165626.19 | E5: =D5*C5 -> 1821888.1 | F5: =AVERAGEIF(U:U,A5,T:T) -> 0.25234891 | H5: 2026 | I5: 4 | J5: 2604204 | K5: ALGEMARIN SPA. | L5: CANAL PROPIO | M5: IZAJE | P5: EDUARDO OÑATE | Q5: 25.537146 | R5: -18.571614 | S5: 6.9655322 | T5: 0.2727608 | U5: 70100294 | V5: GRUA HIAB CL 16 B-3 MARINA | W5: Estrella Rodriguez | X5: 1-PROYECTO COMERCIAL | Y5: Orden fabricación: 70100294 | Z5: 504510 | AA5: 46125 | AB5: ALGEMARIN SPA. | AC5: 91859 | AD5: 76741387-4 | AE5: 70100206 | AF5: 70100206 | AI5: 70100206 | AJ5: GRUA ARTICULADA HIAB X-HIPRO 558 EP-5
A6: 70100165 | B6: GRUA ARTICULADA HIAB X-HIPRO 418 EP-5 | C6: =COUNTIF(U:U,A6) -> 12 | D6: 148036.7 | E6: =D6*C6 -> 1776440.4 | F6: =AVERAGEIF(U:U,A6,T:T) -> 0.26565906 | H6: 2025 | I6: 10 | J6: 2510566 | K6: FRANCISCO ALEJANDRO LEVICAN ANCAHUAI | L6: COMERCIAL ZONA SUR | M6: IZAJE | P6: EDUARDO OÑATE | Q6: 25.498986 | R6: -18.758439 | S6: 6.7405479 | T6: 0.26434572 | U6: 70100294 | V6: GRUA HIAB CL 16 B-3 MARINA | W6: Estrella Rodriguez | X6: 1-PROYECTO COMERCIAL | Y6: Orden fabricación: 70100294 | Z6: 433953 | AA6: 45958 | AB6: FRANCISCO ALEJANDRO LEVICAN ANCAHUAI | AC6: 76985 | AD6: 76741387-4 | AE6: 70100206 | AF6: 70100206 | AI6: 70100165 | AJ6: GRUA ARTICULADA HIAB X-HIPRO 418 EP-5
A7: 70100220 | B7: CAMION GRUA ARTICULADA HIAB X-HIPRO 352 E-6 | C7: =COUNTIF(U:U,A7) -> 1 | D7: 259969.54 | E7: =D7*C7 -> 259969.54 | F7: =AVERAGEIF(U:U,A7,T:T) -> 0.23863632 | H7: 2025 | I7: 12 | J7: 2512426 | K7: LILIANA INES MENDOZA VARGAS SERVICIOS ACUICOLAS TRANSPORTE Y TURISMO EIRL | L7: COMERCIAL ZONA SUR | M7: IZAJE | P7: EDUARDO OÑATE | Q7: 26.239504 | R7: -19.117289 | S7: 7.1222156 | T7: 0.27143103 | U7: 70100294 | V7: GRUA HIAB CL 16 B-3 MARINA | W7: Estrella Rodriguez | X7: 1-PROYECTO COMERCIAL | Y7: Orden fabricación: 70100294 | Z7: 461065 | AA7: 46014 | AB7: LILIANA INES MENDOZA VARGAS SERVICIOS ACUICOLAS TRANSPORTE Y TURISMO EIRL | AC7: 81606 | AD7: 76741387-4 | AE7: 70100206 | AF7: 70100206 | AI7: 70100220 | AJ7: CAMION GRUA ARTICULADA HIAB X-HIPRO 352 E-6
A8: 70100221 | B8: GRUA ARTICULADA HIAB X-HIPRO 858 E-8 | C8: =COUNTIF(U:U,A8) -> 9 | D8: 231940.84 | E8: =D8*C8 -> 2087467.5 | F8: =AVERAGEIF(U:U,A8,T:T) -> 0.2158699 | H8: 2026 | I8: 1 | J8: 2601273 | K8: TRANSPORTE MARITIMO JUAN CARLOS SALAS BORQUEZ EMPRESA INDIVIDUAL DE RESPONSABILIDAD LIMITADA | L8: CANAL PROPIO | M8: IZAJE | P8: EDUARDO OÑATE | Q8: 39.031678 | R8: -27.76635 | S8: 11.265327 | T8: 0.28862012 | U8: 70100289 | V8: GRUA ARTICULADA HIAB X-CL 23 B-4 | W8: Estrella Rodriguez | X8: 1-PROYECTO COMERCIAL | Y8: Facturas clientes - 77062982C | Z8: 476177 | AA8: 46049 | AB8: TRANSPORTE MARITIMO JUAN CARLOS SALAS BORQUEZ EMPRESA INDIVIDUAL DE RESPONSABILIDAD LIMITADA | AC8: 84283 | AD8: 76741387-4 | AE8: 70100206 | AF8: 70100206 | AI8: 70100221 | AJ8: GRUA ARTICULADA HIAB X-HIPRO 858 E-8
A9: 70100171 | B9: GRUA ARTICULADA HIAB X-HIPRO 362 EP-5 | C9: =COUNTIF(U:U,A9) -> 12 | D9: 133753.01 | E9: =D9*C9 -> 1605036.1 | F9: =AVERAGEIF(U:U,A9,T:T) -> 0.33065486 | H9: 2025 | I9: 7 | J9: 2507116 | K9: FIDEL MARTIN BENAVIDES HERRERA | L9: COMERCIAL ZONA SUR | M9: IZAJE | P9: EDUARDO OÑATE | Q9: 37.182278 | R9: -26.192337 | S9: 10.989941 | T9: 0.29556934 | U9: 70100289 | V9: GRUA ARTICULADA HIAB X-CL 23 B-4 | W9: Estrella Rodriguez | X9: 1-PROYECTO COMERCIAL | Y9: Facturas clientes - 12524230C | Z9: 386707 | AA9: 45863 | AB9: FIDEL MARTIN BENAVIDES HERRERA | AC9: 68801 | AD9: 76741387-4 | AE9: 70100165 | AF9: 70100165 | AI9: 70100171 | AJ9: GRUA ARTICULADA HIAB X-HIPRO 362 EP-5
A10: 70100164 | B10: GRUA ARTICULADA HIAB X-HIPRO 408 E-8 | C10: =COUNTIF(U:U,A10) -> 9 | D10: 170285.84 | E10: =D10*C10 -> 1532572.5 | F10: =AVERAGEIF(U:U,A10,T:T) -> 0.25448369 | H10: 2025 | I10: 10 | J10: 2510380 | K10: PESQUERA JUAN SOTO OJEDA E.I.R.L | L10: COMERCIAL ZONA SUR | M10: IZAJE | P10: EDUARDO OÑATE | Q10: 37.135395 | R10: -27.635217 | S10: 9.500178 | T10: 0.25582542 | U10: 70100289 | V10: GRUA ARTICULADA HIAB X-CL 23 B-4 | W10: Jose Pablo Alberto Angulo Procuriza | X10: 1-PROYECTO COMERCIAL | Y10: Orden fabricación: 70100289 | Z10: 430992 | AA10: 45951 | AB10: PESQUERA JUAN SOTO OJEDA E.I.R.L | AC10: 76987 | AD10: 76741387-4 | AE10: 70100165 | AF10: 70100165 | AI10: 70100164 | AJ10: GRUA ARTICULADA HIAB X-HIPRO 408 E-8
A11: 19502062 | B11: GRUA ARTICULADA HIAB X-HIPRO 548 E-9 año 2022 | C11: =COUNTIF(U:U,A11) -> 1 | D11: 191180.5 | E11: =D11*C11 -> 191180.5 | F11: =AVERAGEIF(U:U,A11,T:T) -> 0.25703386 | H11: 2025 | I11: 11 | J11: 2511060 | K11: SOCIEDAD DE SERVICIOS AQUASMART SPA | L11: COMERCIAL ZONA SUR | M11: IZAJE | P11: EDUARDO OÑATE | Q11: 37.500353 | R11: -26.185421 | S11: 11.314932 | T11: 0.30172869 | U11: 70100289 | V11: GRUA ARTICULADA HIAB X-CL 23 B-4 | W11: Jose Pablo Alberto Angulo Procuriza | X11: 1-PROYECTO COMERCIAL | Y11: Orden fabricación: 70100289 | Z11: 447902 | AA11: 45988 | AB11: SOCIEDAD DE SERVICIOS AQUASMART SPA | AC11: 79398 | AD11: 76741387-4 | AE11: 70100165 | AF11: 70100165 | AI11: 19502062 | AJ11: GRUA ARTICULADA HIAB X-HIPRO 548 E-9 año 2022
A12: 70100166 | B12: GRUA ARTICULADA HIAB X-HIDUO 258 EP-5 | C12: =COUNTIF(U:U,A12) -> 7 | D12: 100149.5 | E12: =D12*C12 -> 701046.47 | F12: =AVERAGEIF(U:U,A12,T:T) -> 0.2777657 | H12: 2025 | I12: 12 | J12: 2512054 | K12: MAREAS AUSTRALES SPA | L12: COMERCIAL ZONA SUR | M12: IZAJE | P12: EDUARDO OÑATE | Q12: 36.015165 | R12: -27.015021 | S12: 9.0001438 | T12: 0.24989873 | U12: 70100289 | V12: GRUA ARTICULADA HIAB X-CL 23 B-4 | W12: Estrella Rodriguez | X12: 1-PROYECTO COMERCIAL | Y12: Facturas clientes - 77608032C | Z12: 463219 | AA12: 46020 | AB12: MAREAS AUSTRALES SPA | AC12: 82031 | AD12: 76410374-2 | AE12: 70100220 | AF12: 70100220 | AI12: 70100166 | AJ12: GRUA ARTICULADA HIAB X-HIDUO 258 EP-5
A13: 70100289 | B13: GRUA ARTICULADA HIAB X-CL 23 B-4 | C13: =COUNTIF(U:U,A13) -> 5 | D13: 37372.974 | E13: =D13*C13 -> 186864.87 | F13: =AVERAGEIF(U:U,A13,T:T) -> 0.27832846 | H13: 2026 | I13: 3 | J13: 2603063 | K13: VICTOR HUGO ITURRA ZUNIGA ARRIENDO DE VEHICULOS Y TRANSPORTE DE PASAJ | L13: CANAL PROPIO | M13: IZAJE | O13: ZONA CENTRO - SANTIAGO | P13: CARLOS SOTO | Q13: 142.06115 | R13: -108.5682 | S13: 33.492949 | T13: 0.23576431 | U13: 70100275 | V13: GRUA ARTICULADA HIAB X HIPRO 558 EP6 | W13: Estrella Rodriguez | X13: 1-PROYECTO COMERCIAL | Y13: RECLASIFICA PREVENTA MANTENCION CLIENTE VICTOR ITURRA | Z13: 504186 | AA13: 46122 | AB13: VICTOR HUGO ITURRA ZUNIGA ARRIENDO DE VEHICULOS Y TRANSPORTE DE PASAJ | AC13: 88938 | AD13: 76238635-6 | AE13: 70100221 | AF13: 70100221 | AI13: 70100289 | AJ13: GRUA ARTICULADA HIAB X-CL 23 B-4
A14: 70100212 | B14: GRUA ARTICULADA HIAB X-HIPRO 638 E-9 | C14: =COUNTIF(U:U,A14) -> 7 | D14: 194022.49 | E14: =D14*C14 -> 1358157.4 | F14: =AVERAGEIF(U:U,A14,T:T) -> 0.093299565 | H14: 2026 | I14: 5 | J14: 2603701 | K14: G.T.A. CHILE SPA | L14: CANAL PROPIO | M14: IZAJE | P14: EDGARDO URREA | Q14: 176.81475 | R14: -245.24964 | S14: -68.434887 | T14: -0.38704286 | U14: 70100275 | V14: GRUA ARTICULADA HIAB X HIPRO 558 EP6 | W14: Estrella Rodriguez | X14: 1-PROYECTO COMERCIAL | Y14: Orden fabricación: 81310205 | Z14: 529941 | AA14: 46178 | AB14: G.T.A. CHILE SPA | AC14: 94488 | AD14: 96572360-9 | AE14: 70100206 | AF14: 70100206 | AI14: 70100212 | AJ14: GRUA ARTICULADA HIAB X-HIPRO 638 E-9
A15: 70100200 | B15: GRUA ARTICULADA HIAB X-CLX 248 EP-4 MARINA | C15: =COUNTIF(U:U,A15) -> 1 | D15: 43944.303 | E15: =D15*C15 -> 43944.303 | F15: =AVERAGEIF(U:U,A15,T:T) -> 0.2007608 | H15: 2026 | I15: 5 | J15: 2603702 | K15: G.T.A. CHILE SPA | L15: CANAL PROPIO | M15: IZAJE | P15: EDGARDO URREA | Q15: 176.81475 | R15: -15.163274 | S15: 161.65148 | T15: 0.91424203 | U15: 70100275 | V15: GRUA ARTICULADA HIAB X HIPRO 558 EP6 | W15: Estrella Rodriguez | X15: 1-PROYECTO COMERCIAL | Y15: Orden fabricación: 81310205 | Z15: 529924 | AA15: 46178 | AB15: G.T.A. CHILE SPA | AC15: 94231 | AD15: 91502000-3 | AE15: 70100171 | AF15: 70100171 | AI15: 70100200 | AJ15: GRUA ARTICULADA HIAB X-CLX 248 EP-4 MARINA
A16: 70100195 | B16: GRUA ARTICULADA HIAB X-CLX 288 EP-4 MARINA | C16: =COUNTIF(U:U,A16) -> 1 | D16: 53504.385 | E16: =D16*C16 -> 53504.385 | F16: =AVERAGEIF(U:U,A16,T:T) -> 0.16841542 | H16: 2025 | I16: 10 | J16: 2509575 | K16: SALINAS Y FABRES SOCIEDAD ANONIMA | L16: COMERCIAL ZONA CENTRO | M16: IZAJE | P16: CARLOS SOTO | Q16: 170.0204 | R16: -121.93444 | S16: 48.085959 | T16: 0.28282465 | U16: 70100275 | V16: GRUA ARTICULADA HIAB X HIPRO 558 EP6 | W16: Javier Ballesteros | X16: 1-PROYECTO COMERCIAL | Y16: Orden fabricación: 70100275 | Z16: 435487 | AA16: 45960 | AB16: SALINAS Y FABRES SOCIEDAD ANONIMA | AC16: 77135 | AD16: 91502000-3 | AE16: 70100171 | AF16: 70100171 | AI16: 70100195 | AJ16: GRUA ARTICULADA HIAB X-CLX 288 EP-4 MARINA
A17: 70100173 | B17: CAMION GRUA ARTICULADA HIAB X-HIPRO 418 EP-5 | C17: =COUNTIF(U:U,A17) -> 4 | D17: 309614.95 | E17: =D17*C17 -> 1238459.8 | F17: =AVERAGEIF(U:U,A17,T:T) -> 0.14202945 | H17: 2025 | I17: 11 | J17: 2508638 | K17: CONSTRUCTORA SALFA S A | L17: COMERCIAL ZONA CENTRO | M17: IZAJE | P17: CARLOS SOTO | Q17: 164.54634 | R17: -130.11366 | S17: 34.432683 | T17: 0.20925827 | U17: 70100275 | V17: GRUA ARTICULADA HIAB X HIPRO 558 EP6 | W17: Estrella Rodriguez | X17: 1-PROYECTO COMERCIAL | Y17: Orden fabricación: 70100206 | Z17: 446921 | AA17: 45987 | AB17: CONSTRUCTORA SALFA S A | AC17: 79164 | AD17: 96572360-9 | AE17: 70100164 | AF17: 70100164 | AI17: 70100173 | AJ17: CAMION GRUA ARTICULADA HIAB X-HIPRO 418 EP-5
A18: 70100205 | B18: GRUA ARTICULADA HIAB X-HIPRO 548 E-9 | C18: =COUNTIF(U:U,A18) -> 3 | D18: 189094.54 | E18: =D18*C18 -> 567283.62 | F18: =AVERAGEIF(U:U,A18,T:T) -> 0.19410197 | H18: 2025 | I18: 12 | J18: 2510654 | K18: COMERCIAL KAUFMANN S.A. | L18: COMERCIAL ZONA CENTRO | M18: IZAJE | P18: CARLOS SOTO | Q18: 179.56754 | R18: -118.14962 | S18: 61.41792 | T18: 0.34203243 | U18: 70100275 | V18: GRUA ARTICULADA HIAB X HIPRO 558 EP6 | W18: Estrella Rodriguez | X18: 1-PROYECTO COMERCIAL | Y18: Orden fabricación: 70100275 | Z18: 464746 | AA18: 46021 | AB18: COMERCIAL KAUFMANN S.A. | AC18: 81437 | AD18: 96572360-9 | AE18: 19502062 | AF18: 19502062 | AI18: 70100205 | AJ18: GRUA ARTICULADA HIAB X-HIPRO 548 E-9
A19: 70100167 | B19: GRUA ARTICULADA HIAB X-HIDUO 298 EP-5 | C19: =COUNTIF(U:U,A19) -> 4 | D19: 111290.72 | E19: =D19*C19 -> 445162.88 | F19: =AVERAGEIF(U:U,A19,T:T) -> 0.23659897 | H19: 2026 | I19: 3 | J19: 2511052 | K19: COMERCIAL KAUFMANN S.A. | L19: CANAL KAUFMANN | M19: IZAJE | O19: ZONA CENTRO - SANTIAGO | P19: KEVIN FLEFEL | Q19: 184.27065 | R19: -152.9253 | S19: 31.345342 | T19: 0.17010491 | U19: 70100267 | V19: GRUA ARTICULADA HIAB X-HIPRO 548 E-9 año 2022 | W19: Estrella Rodriguez | X19: 1-PROYECTO COMERCIAL | Y19: RECLASIFICA VENTA POR SERV DE MANTENCION | Z19: 502243 | AA19: 46120 | AB19: COMERCIAL KAUFMANN S.A. | AC19: 88913 | AD19: 76496130-7 | AE19: 70100166 | AF19: 70100166 | AI19: 70100167 | AJ19: GRUA ARTICULADA HIAB X-HIDUO 298 EP-5
A20: 70100275 | B20: GRUA ARTICULADA HIAB X HIPRO 558 EP6 | C20: =COUNTIF(U:U,A20) -> 6 | D20: 168304.15 | E20: =D20*C20 -> 1009824.9 | F20: =AVERAGEIF(U:U,A20,T:T) -> 0.26617981 | H20: 2025 | I20: 12 | J20: 2509339 | K20: WORLD CLASS MINING SERVICES Y COMPANIA LTDA | L20: COMERCIAL ZONA NORTE | M20: IZAJE | P20: EDGARDO URREA | Q20: 291.25626 | R20: -240.59842 | S20: 50.657838 | T20: 0.17392875 | U20: 70100259 | V20: CAMION GRUA ARTICULADA HIAB X-HIDUO 188 E5 | W20: Estrella Rodriguez | X20: 1-PROYECTO COMERCIAL | Y20: Orden fabricación: 70100259 | Z20: 460505 | AA20: 46013 | AB20: CONSTRUCCIÓN E INGENIERÍA ELÉCTRICA HÉCTOR DAVID QUISBERT VARGAS E.I.R | AC20: 82014 | AD20: 76178493-5 | AE20: 70100165 | AF20: 70100165 | AI20: 70100275 | AJ20: GRUA ARTICULADA HIAB X HIPRO 558 EP6
A21: 70100225 | B21: GRUA ARTICULADA HIAB X-CLX 088 E-4 | C21: =COUNTIF(U:U,A21) -> 1 | D21: 65629.41 | E21: =D21*C21 -> 65629.41 | F21: =AVERAGEIF(U:U,A21,T:T) -> 0.16464444 | H21: 2026 | I21: 1 | J21: 2601519 | K21: SOCIEDAD DE TRANSPORTE MARITIMO Y TERRESTRE BAHAMONDE Y CIA LTDA | L21: CANAL PROPIO | M21: IZAJE | P21: EDUARDO OÑATE | Q21: 72.468825 | R21: -60.417549 | S21: 12.051276 | T21: 0.16629601 | U21: 70100253 | V21: GRUA HIAB X-CLX 388 EP5 | W21: Estrella Rodriguez | X21: 1-PROYECTO COMERCIAL | Y21: Facturas clientes - 76039220C | Z21: 478109 | AA21: 46052 | AB21: SOCIEDAD DE TRANSPORTE MARITIMO Y TERRESTRE BAHAMONDE Y CIA LTDA | AC21: 84280 | AD21: 97036000-K | AE21: 70100171 | AF21: 70100171 | AI21: 70100225 | AJ21: GRUA ARTICULADA HIAB X-CLX 088 E-4
A22: 70100249 | B22: GRUA ARTICULADA HIAB X-CLX 178 E-4 | C22: =COUNTIF(U:U,A22) -> 9 | D22: 89855.865 | E22: =D22*C22 -> 808702.79 | F22: =AVERAGEIF(U:U,A22,T:T) -> 0.20109067 | H22: 2026 | I22: 2 | J22: 2602337 | K22: MANUEL BARRIENTOS RETAMAL | L22: CANAL PROPIO | M22: IZAJE | P22: EDUARDO OÑATE | Q22: 72.946097 | R22: -59.836219 | S22: 13.109878 | T22: 0.17972007 | U22: 70100253 | V22: GRUA HIAB X-CLX 388 EP5 | W22: Estrella Rodriguez | X22: 1-PROYECTO COMERCIAL | Y22: Facturas clientes - 6097476C | Z22: 486303 | AA22: 46079 | AB22: MANUEL BARRIENTOS RETAMAL | AC22: 86184 | AD22: 12524230-8 | AE22: 70100289 | AF22: 70100289 | AI22: 70100249 | AJ22: GRUA ARTICULADA HIAB X-CLX 178 E-4
A23: 70100259 | B23: CAMION GRUA ARTICULADA HIAB X-HIDUO 188 E5 | C23: =COUNTIF(U:U,A23) -> 1 | D23: 291256.26 | E23: =D23*C23 -> 291256.26 | F23: =AVERAGEIF(U:U,A23,T:T) -> 0.17392875 | H23: 2026 | I23: 3 | J23: 2602274 | K23: COMERCIAL KAUFMANN S.A. | L23: CANAL KAUFMANN | M23: IZAJE | O23: ZONA CENTRO - SANTIAGO | P23: KEVIN FLEFEL | Q23: 87.277857 | R23: -65.724378 | S23: 21.553479 | T23: 0.24695243 | U23: 70100251 | V23: GRUA ARTICULADA HIAB X-HIDUO 188 E-5 | W23: Estrella Rodriguez | X23: 1-PROYECTO COMERCIAL | Y23: Facturas clientes - 96572360C | Z23: 500442 | AA23: 46112 | AB23: COMERCIAL KAUFMANN S.A. | AC23: 88910 | AD23: 76238635-6 | AE23: 70100221 | AF23: 70100221 | AI23: 70100259 | AJ23: CAMION GRUA ARTICULADA HIAB X-HIDUO 188 E5
A24: 70100247 | B24: GRUA ARTICULADA HIAB IQ 1188 E-9 JIB | C24: =COUNTIF(U:U,A24) -> 1 | D24: 378014.06 | E24: =D24*C24 -> 378014.06 | F24: =AVERAGEIF(U:U,A24,T:T) -> 0.21285273 | H24: 2026 | I24: 5 | J24: 2604264 | K24: TRANSPORTES BELLO E HIJOS Y LTDA. | L24: CANAL PROPIO | M24: IZAJE | P24: FRANCO MODINGER | Q24: 92.631368 | R24: -70.22552 | S24: 22.405849 | T24: 0.24188187 | U24: 70100249 | V24: GRUA ARTICULADA HIAB X-CLX 178 E-4 | W24: Estrella Rodriguez | X24: 1-PROYECTO COMERCIAL | Y24: Orden fabricación: 70100249 | Z24: 520725 | AA24: 46156 | AB24: TRANSPORTES BELLO E HIJOS Y LTDA. | AC24: 92938 | AD24: 76238635-6 | AE24: 70100212 | AF24: 70100212 | AI24: 70100247 | AJ24: GRUA ARTICULADA HIAB IQ 1188 E-9 JIB
A25: 70100157 | B25: GRUA HIAB X-CL 8 B3 | C25: =COUNTIF(U:U,A25) -> 1 | D25: 72256.158 | E25: =D25*C25 -> 72256.158 | F25: =AVERAGEIF(U:U,A25,T:T) -> 0.20010266 | H25: 2026 | I25: 5 | J25: 2604501 | K25: CULTIVOS CARLOS ÁLVARO RAIN MACÍAS E.I.R.L | L25: CANAL PROPIO | M25: IZAJE | P25: EDUARDO OÑATE | Q25: 73.944917 | R25: -55.85713 | S25: 18.087787 | T25: 0.24461164 | U25: 70100249 | V25: GRUA ARTICULADA HIAB X-CLX 178 E-4 | W25: Estrella Rodriguez | X25: 1-PROYECTO COMERCIAL | Y25: Entregas - 78002854C | Z25: 529956 | AA25: 46178 | AB25: CULTIVOS CARLOS ÁLVARO RAIN MACÍAS E.I.R.L | AC25: 95287 | AD25: 76386938-5 | AE25: 70100200 | AF25: 70100200 | AI25: 70100157 | AJ25: GRUA HIAB X-CL 8 B3
A26: 70100294 | B26: GRUA HIAB CL 16 B-3 MARINA | C26: =COUNTIF(U:U,A26) -> 5 | D26: 25727.359 | E26: =D26*C26 -> 128636.8 | F26: =AVERAGEIF(U:U,A26,T:T) -> 0.26505418 | H26: 2025 | I26: 11 | J26: 2509155 | K26: AGENCIAS UNIVERSALES S A | L26: COMERCIAL ZONA CENTRO | M26: IZAJE | P26: BENJAMIN FUENZALIDA | Q26: 91.732357 | R26: -74.575502 | S26: 17.156855 | T26: 0.18703166 | U26: 70100249 | V26: GRUA ARTICULADA HIAB X-CLX 178 E-4 | W26: Estrella Rodriguez | X26: 1-PROYECTO COMERCIAL | Y26: Orden fabricación: 70100249 | Z26: 446105 | AA26: 45985 | AB26: AGENCIAS UNIVERSALES S A | AC26: 78961 | AD26: 77789445-5 | AE26: 70100195 | AF26: 70100195 | AI26: 70100294 | AJ26: GRUA HIAB CL 16 B-3 MARINA
A27: 70100174 | B27: CAMION GRUA ARTICULADA HIAB X-HIPRO 558 EP-5 | C27: =COUNTIF(U:U,A27) -> 2 | D27: 337867.94 | E27: =D27*C27 -> 675735.88 | F27: =AVERAGEIF(U:U,A27,T:T) -> 0.15732089 | H27: 2025 | I27: 11 | J27: 2509156 | K27: AGENCIAS UNIVERSALES S A | L27: COMERCIAL ZONA CENTRO | M27: IZAJE | P27: BENJAMIN FUENZALIDA | Q27: 91.732357 | R27: -72.72675 | S27: 19.005607 | T27: 0.20718543 | U27: 70100249 | V27: GRUA ARTICULADA HIAB X-CLX 178 E-4 | W27: Estrella Rodriguez | X27: 1-PROYECTO COMERCIAL | Y27: Orden fabricación: 70100249 | Z27: 448717 | AA27: 45989 | AB27: AGENCIAS UNIVERSALES S A | AC27: 79379 | AD27: 97006000-6 | AE27: 70100173 | AF27: 70100173 | AI27: 70100174 | AJ27: CAMION GRUA ARTICULADA HIAB X-HIPRO 558 EP-5
A28: 70100267 | B28: GRUA ARTICULADA HIAB X-HIPRO 548 E-9 año 2022 | C28: =COUNTIF(U:U,A28) -> 1 | D28: 184270.65 | E28: =D28*C28 -> 184270.65 | F28: =AVERAGEIF(U:U,A28,T:T) -> 0.17010491 | H28: 2025 | I28: 11 | J28: 2509157 | K28: AGENCIAS UNIVERSALES S A | L28: COMERCIAL ZONA CENTRO | M28: IZAJE | P28: BENJAMIN FUENZALIDA | Q28: 91.732357 | R28: -72.819033 | S28: 18.913324 | T28: 0.20617942 | U28: 70100249 | V28: GRUA ARTICULADA HIAB X-CLX 178 E-4 | W28: Estrella Rodriguez | X28: 1-PROYECTO COMERCIAL | Y28: Orden fabricación: 70100249 | Z28: 447719 | AA28: 45988 | AB28: AGENCIAS UNIVERSALES S A | AC28: 79374 | AD28: 10201610-6 | AE28: 70100164 | AF28: 70100164 | AI28: 70100267 | AJ28: GRUA ARTICULADA HIAB X-HIPRO 548 E-9 año 2022
A29: 70100169 | B29: GRUA ARTICULADA HIAB X-HIPRO 302 E-8 | C29: =COUNTIF(U:U,A29) -> 1 | D29: 141626.23 | E29: =D29*C29 -> 141626.23 | F29: =AVERAGEIF(U:U,A29,T:T) -> 0.32849697 | H29: 2025 | I29: 11 | J29: 2509158 | K29: AGENCIAS UNIVERSALES S A | L29: COMERCIAL ZONA CENTRO | M29: IZAJE | P29: BENJAMIN FUENZALIDA | Q29: 91.732357 | R29: -75.360313 | S29: 16.372044 | T29: 0.17847621 | U29: 70100249 | V29: GRUA ARTICULADA HIAB X-CLX 178 E-4 | W29: Estrella Rodriguez | X29: 1-PROYECTO COMERCIAL | Y29: Orden fabricación: 70100249 | Z29: 445538 | AA29: 45982 | AB29: AGENCIAS UNIVERSALES S A | AC29: 78973 | AD29: 76367961-6 | AE29: 70100206 | AF29: 70100206 | AI29: 70100169 | AJ29: GRUA ARTICULADA HIAB X-HIPRO 302 E-8
A30: 70100159 | B30: GRUA ARTICULADA HIAB X-HIPRO 362 EP-5 EVO | C30: =COUNTIF(U:U,A30) -> 13 | D30: 111962.9 | E30: =D30*C30 -> 1455517.7 | F30: =AVERAGEIF(U:U,A30,T:T) -> -0.0068320273 | H30: 2025 | I30: 11 | J30: 2509159 | K30: AGENCIAS UNIVERSALES S A | L30: COMERCIAL ZONA CENTRO | M30: IZAJE | P30: BENJAMIN FUENZALIDA | Q30: 91.732357 | R30: -75.12157 | S30: 16.610787 | T30: 0.18107882 | U30: 70100249 | V30: GRUA ARTICULADA HIAB X-CLX 178 E-4 | W30: Estrella Rodriguez | X30: 1-PROYECTO COMERCIAL | Y30: Orden fabricación: 70100249 | Z30: 441152 | AA30: 45978 | AB30: AGENCIAS UNIVERSALES S A | AC30: 78381 | AD30: 76367961-6 | AE30: 70100206 | AF30: 70100206 | AI30: 70100159 | AJ30: GRUA ARTICULADA HIAB X-HIPRO 362 EP-5 EVO
A31: 70100160 | B31: GRUA ARTICULADA HIAB X-HIPRO 558 EP-6 EVO | C31: =COUNTIF(U:U,A31) -> 3 | D31: 142118.08 | E31: =D31*C31 -> 426354.25 | F31: =AVERAGEIF(U:U,A31,T:T) -> -0.015329346 | H31: 2025 | I31: 11 | J31: 2509160 | K31: AGENCIAS UNIVERSALES S A | L31: COMERCIAL ZONA CENTRO | M31: IZAJE | P31: BENJAMIN FUENZALIDA | Q31: 91.732357 | R31: -74.850121 | S31: 16.882236 | T31: 0.18403796 | U31: 70100249 | V31: GRUA ARTICULADA HIAB X-CLX 178 E-4 | W31: Estrella Rodriguez | X31: 1-PROYECTO COMERCIAL | Y31: Orden fabricación: 70100249 | Z31: 447190 | AA31: 45987 | AB31: AGENCIAS UNIVERSALES S A | AC31: 79151 | AD31: 76367961-6 | AE31: 70100206 | AF31: 70100206 | AI31: 70100160 | AJ31: GRUA ARTICULADA HIAB X-HIPRO 558 EP-6 EVO
A32: 13171059 | B32: GRUA ARTICULADA HIAB X-CLX 288 EP-5 MARINA | C32: =COUNTIF(U:U,A32) -> 1 | D32: =Q145*1000 -> 53393.206 | E32: =D32*C32 -> 53393.206 | F32: =AVERAGEIF(U:U,A32,T:T) -> 0.18185622 | H32: 2025 | I32: 11 | J32: 2509162 | K32: AGENCIAS UNIVERSALES S A | L32: COMERCIAL ZONA CENTRO | M32: IZAJE | P32: BENJAMIN FUENZALIDA | Q32: 91.732357 | R32: -75.281719 | S32: 16.450638 | T32: 0.17933299 | U32: 70100249 | V32: GRUA ARTICULADA HIAB X-CLX 178 E-4 | W32: Estrella Rodriguez | X32: 1-PROYECTO COMERCIAL | Y32: Orden fabricación: 70100249 | Z32: 444594 | AA32: 45980 | AB32: AGENCIAS UNIVERSALES S A | AC32: 78604 | AD32: 91502000-3 | AE32: 70100212 | AF32: 70100212 | AI32: 13171059 | AJ32: GRUA ARTICULADA HIAB X-CLX 288 EP-5 MARINA
A33: 70100253 | B33: GRUA HIAB X-CLX 388 EP5 | C33: =COUNTIF(U:U,A33) -> 2 | D33: 72707.461 | E33: =D33*C33 -> 145414.92 | F33: =AVERAGEIF(U:U,A33,T:T) -> 0.17300804 | H33: 2025 | I33: 12 | J33: 2510159 | K33: SWITCH CHILE SERVICIOS LIMITADA | L33: COMERCIAL ZONA CENTRO | M33: IZAJE | P33: CARLOS SOTO | Q33: 378.01406 | R33: -297.55274 | S33: 80.461326 | T33: 0.21285273 | U33: 70100247 | V33: GRUA ARTICULADA HIAB IQ 1188 E-9 JIB | W33: Estrella Rodriguez | X33: 1-PROYECTO COMERCIAL | Y33: Orden fabricación: 70100247 | Z33: 464828 | AA33: 46021 | AB33: SWITCH CHILE SERVICIOS LIMITADA | AC33: 81827 | AD33: 96572360-9 | AE33: 70100164 | AF33: 70100164 | AI33: 70100253 | AJ33: GRUA HIAB X-CLX 388 EP5
A34: 70100043 | B34: GRUA HIAB X-CL 12 B3 | C34: =COUNTIF(U:U,A34) -> 1 | D34: 54843.88 | E34: =D34*C34 -> 54843.88 | F34: =AVERAGEIF(U:U,A34,T:T) -> 0.039361899 | H34: 2025 | I34: 12 | J34: 2509149 | K34: AGENCIAS UNIVERSALES S A | L34: COMERCIAL ZONA CENTRO | M34: IZAJE | P34: BENJAMIN FUENZALIDA | Q34: 65.62941 | R34: -54.823893 | S34: 10.805517 | T34: 0.16464444 | U34: 70100225 | V34: GRUA ARTICULADA HIAB X-CLX 088 E-4 | W34: Gloria ZuÃ±iga | X34: 1-PROYECTO COMERCIAL | Y34: reconoce Difiere Facturas clientes - 96566940C(Anulación) - 450552 | Z34: 467531 | AA34: 46028 | AB34: AGENCIAS UNIVERSALES S A | AC34: 80056 | AD34: 97023000-9 | AE34: 70100205 | AF34: 70100205 | AI34: 70100043 | AJ34: GRUA HIAB X-CL 12 B3
A35: 70100251 | B35: GRUA ARTICULADA HIAB X-HIDUO 188 E-5 | C35: =COUNTIF(U:U,A35) -> 1 | D35: 87277.857 | E35: =D35*C35 -> 87277.857 | F35: =AVERAGEIF(U:U,A35,T:T) -> 0.24695243 | H35: 2026 | I35: 1 | J35: 2509556 | K35: SALINAS Y FABRES SOCIEDAD ANONIMA | L35: CANAL PROPIO | M35: IZAJE | O35: ZONA NORTE - ANTOFAGASTA | P35: EDGARDO URREA | Q35: 257.14699 | R35: -175.01746 | S35: 82.129529 | T35: 0.31938748 | U35: 70100221 | V35: GRUA ARTICULADA HIAB X-HIPRO 858 E-8 | W35: Cristina Fuentes | X35: 1-PROYECTO COMERCIAL | Y35: Difiere Facturas clientes - 91502000C(Anulación) - 468090 | Z35: 481470 | AA35: 46076 | AB35: SOC CONTRACTUAL MINERA EL ABRA | AC35: 82197 | AD35: 96572360-9 | AE35: 70100167 | AF35: 70100167 | AI35: 70100251 | AJ35: GRUA ARTICULADA HIAB X-HIDUO 188 E-5
